Workbook

Sheet 00_Instrucciones
A1: MASTER CONEXIÓN FORMULARIO → ORDEN DE TRABAJO IM
A2: Objetivo | B2: Recibir solicitudes de Microsoft Forms, normalizarlas y generar automáticamente una OT maestra con trazabilidad de Diseño, Preprensa, Producción, Calidad y Cierre.
A3: Paso | B3: Responsable | C3: Acción en el archivo | D3: Hoja | E3: Resultado esperado | F3: Observación
A4: 1 | B4: Cliente interno | C4: Diligencia Microsoft Forms | D4: Formulario externo | E4: Registro de solicitud | F4: Link en hoja Catalogos
A5: 2 | B5: Coordinador / Imprenta | C5: Pega o actualiza export de Forms en 01_Forms_Raw | D5: 01_Forms_Raw | E5: Datos crudos recibidos | F5: No editar fórmulas en hojas 02 y 03
A6: 3 | B6: Sistema Excel | C6: Normaliza campos, genera número OT y valida información | D6: 02_Base_Solicitudes | E6: Solicitud lista para OT | F6: Campos verdes = calculados
A7: 4 | B7: Diseño / Comunicaciones | C7: Completa arte, aprobación del cliente y proveedor de planchas | D7: 03_OT_Maestra | E7: Diseño aprobado o pendiente | F7: Campos amarillos = editar
A8: 5 | B8: Preprensa / Imprenta | C8: Completa especificación técnica, material, máquina, inventario y producción | D8: 03_OT_Maestra | E8: OT lista para producir | F8: Incluye input del Sr. Julio / operador
A9: 6 | B9: Calidad / Cierre | C9: Registra control de calidad, entrega, fecha cierre y estado | D9: 03_OT_Maestra | E9: Trazabilidad completa y KPIs | F9: Dashboard automático
A11: Convención de colores | B11: Azul = encabezados | C11: Amarillo = campos editables | D11: Verde = campos calculados | E11: Naranja = alertas / SLA
A13: A (concepto) | B13: B (regla)
A14: Regla de unidades | B14: Entrega Parcial y Cantidad producida miden cosas distintas. Nunca se suman entre sí.
A15: Entrega Parcial | B15: Acumulado entregado a la fecha. Se sobrescribe en cada entrega con el nuevo acumulado (ej. 146 → 288 → 500). Nunca se digita solo lo de esa entrega.
A16: Cantidad producida | B16: Total final de unidades terminadas. Se llena al cerrar la OT. No usar para avances parciales.
A17: Mientras la OT está abierta | B17: Solo se actualiza Entrega Parcial. El dashboard la toma como contador de unidades producidas.
A18: Al cerrar la OT | B18: Se digita Cantidad producida (valor final) y Fecha cierre. El parcial se deja como quedó. El KPI usa únicamente Cantidad producida.
A19: Producido ≠ entregado | B19: Si difieren (ej. 1.152 producidas, 1.000 entregadas), se deja así. La diferencia es inventario y debe quedar explicada en Observaciones cierre.
A20: Integridad Estado OT ↔ Fecha cierre | B20: Fecha cierre y Estado OT = Cerrada van siempre juntos. Primero se selecciona el Estado OT y luego se digita la fecha (Excel no deja digitar Fecha cierre si el estado no es Cerrada). La columna Integridad (AK) marca en rojo "⚠ Cerrada incompleta" (Cerrada sin Fecha entrega, Recibido por o Fecha cierre) o "⚠ Fecha cierre con estado abierto". Solo "OK" se considera válida; el dashboard muestra una alerta por cada inconsistencia.
A21: Fuentes internas del proyecto
A22: Solicitud Servicio_V1_Imprenta UM.xlsx | B22: Export de Microsoft Forms con campos del solicitante y solicitudes ejemplo
A23: OT_Maestra_V1_Imprenta_UM_Modelo.xlsx | B23: Base conceptual de OT Maestra con secciones de diseño, preprensa, producción y cierre
A24: Flujo Proceso_Imprenta_UM v1.2.pptx / Proyecto Reactivación PDF | B24: Proceso recomendado: Solicitud Digital → Diseño → Compras Planchas → Preprensa → Producción → Calidad → Entrega/KPIs
A26: Control de versiones
A27: v2 (2026-08-13) | B27: 03_OT_Maestra: "Estado OT" se reubica junto a "Fecha cierre"; se elimina "Versión diseño". Se actualizaron OTMaestraTable, 04_OT_Print001 y 06_Dashboard. Base preparada para automatización (Power Automate).
A29: v2.1 (2026-10-05) | B29: 03_OT_Maestra: se define la regla de unidades Entrega Parcial (acumulado entregado, se sobrescribe) vs. Cantidad producida (total final al cierre). El dashboard usa el parcial como contador en OTs abiertas y Cantidad producida en OTs cerradas. Sin cambios de columnas ni fórmulas.
A30: v2.2 (2026-10-07) | B30: 03_OT_Maestra: se agrega la columna AK "Integridad" (Estado OT vs. Fecha cierre) con formato condicional rojo/verde; Observaciones cierre pasa de AK a AL. Validación personalizada en Fecha cierre (AG): solo se digita si Estado OT = Cerrada. Regla documentada en 00_Instrucciones fila 20.

Sheet 01_Forms_Raw
A1: Id | B1: Start time | C1: Completion time | D1: Dependencia / Área solicitante | E1: Nombre del solicitante | F1: Cargo | G1: Correo institucional | H1: Fecha de solicitud | I1: Nombre del trabajo solicitado | J1: Tipo de pieza gráfica | K1: Cantidad requerida | L1: Fecha requerida de entrega | M1: Comentarios adicionales
A2: 1 | B2: 46164.682 | C2: 46164.686 | D2: Rectoria - Comunicaciones y Mercadeo | E2: Camilo Robledo | F2: Coordinador Contenido | G2: coordinadordecontenidos@unimetro.edu.co | H2: 46185 | I2: Miniblocks - Mercadeo / pieza promocional unimetro | J2: MiniBlocks | K2: 750 | L2: 46233 | M2: Mini Blocks pedido de Vicerrectoria. Se entregan 50 unidades a Julio Higgins para campaña mercadeo del Dpto de Diseño y Comunicaciones. El resto de la producción se entregará a Rectoría
A3: 2 | B3: 46164.686 | C3: 46164.688 | D3: Rectoria - Comunicaciones y Mercadeo | E3: Camilo Robledo | F3: Coordinador Comunicaciones | G3: coordinadordecontenidos@unimetro.edu.co | H3: 46185 | I3: Memos - pieza de mercadeo para el area de comunicaciones | J3: Memos | K3: 570 | L3: 46310 | M3: Mini Memos pedido de Vicerrectoria. Se entregan 50 unidades a Julio Higgins para campaña mercadeo del Dpto de Diseño y Comunicaciones
A4: 3 | B4: 46164.69 | C4: 46164.704 | D4: Vicerrectoria | E4: Jose Luis Castro Guerra | F4: Vicerrector | G4: vice-rectoria@unimetro.edu.co | H4: 46160 | I4: Agendas - Material interno y de distribución externa para segundo semestre 2026 | J4: Agendas | K4: 500 | L4: 46230 | M4: Material de la Agendas ya se adquirió. Al 11 de Junio la planchas están en proceso de elaboración por proveedor. Se requiere tecnico empastador para apoyar con el ensamble de las agendas
A5: 4 | B5: 46164.704 | C5: 46164.737 | D5: Vicerrectoria | E5: Jose Luis Castro | F5: Vicerrector | G5: vice-rectoria@unimetro.edu.co | H5: 46254 | I5: Abanicos - Material de promoción de la universidad | J5: Abanicos | K5: 1500 | L5: 46324 | M5: Los abanicos hacen parte de un material de promoción. Todavía no tiene aprobación de Rectoría
A6: 5 | B6: 46167.394 | C6: 46167.397 | D6: Vicerrectoria | E6: Indira Luz de la Rosa | F6: Asistente Vicerectoria | G6: idelarosa@unimetro.edu.co | H6: 46153 | I6: Actas de Grado | J6: Actas de grado | K6: 1000 | L6: 46184 | M6: Cotizar papel Opalina . Sr Julio Rivera consiguió la cotización de 150 pliegos en Dipaca - distribuidora papelera del caribe.
A7: 6 | B7: 46167.398 | C7: 46167.41 | D7: Vicerrectoria - Biblioteca | E7: Yarima Medrano Nazzer | F7: Directora Biblioteca | G7: directorabiblioteca@unimetro.edu.co | H7: 46121 | I7: Tarjetas de Prestamo | J7: Tarjetas Prestamo Biblioteca | K7: 5000 | L7: 46259 | M7: Esta solicitud tuvo una demora causada por el material que llego solo hasta el 4 de mayo.
A8: 7 | B8: 46167.41 | C8: 46167.413 | D8: Vicerrectoria - Biblioteca | E8: Yarima Medrano Nazzer | F8: Directora Biblioteca | G8: directorabiblioteca@unimetro.edu.co | H8: 46121 | I8: Bolsillos de tarjeta de préstamo | J8: Bolsillos de tarjeta de préstamo | K8: 2000 | L8: 46259 | M8: Material pedido en Febrero solo se recepcionó hasta inicios de Mayo.
A9: 8 | B9: 46167.413 | C9: 46167.419 | D9: Vicerrectoria - Biblioteca | E9: Yarima Medrano Nazzer | F9: Directora Biblioteca | G9: directorabiblioteca@unimetro.edu.co | H9: 46121 | I9: Adhesivos de Colores para categorizar grupos de Libros | J9: Adhesivos de Colores | K9: 1300 | L9: 46155 | M9: Se realizaran adhesivos tamaño carta Amarillo, verde, rosado, gris, azul - 500/200/200/200/200. Se entregaron el 11 de Mayo
A10: 9 | B10: 46177.929 | C10: 46177.93 | D10: Vicerrectoria - Direccion Administrativa | E10: Elio Ortiz | F10: Director Administrativo | G10: eortizg@unimetro.edu.co | H10: 46170 | I10: Hojas membretadas uso institucional para varias dependencias | J10: Hojas Membreteadas | K10: 5000 | L10: 46249 | M10: Se estima que para finalesde junio se debe tener la hojas membretadas para el uso en varias dependencias.
A11: 10 | B11: 46178.649 | C11: 46178.655 | D11: Rectoria - Alta consejeria | E11: Julian Ramirez | F11: Coordinador Imprenta UM | G11: jramirezo@unimetro.edu.co | H11: 46155 | I11: Individuales para bandejas de plazoleta de comidas | J11: Individuales para bandejas | K11: 3600 | L11: 46254 | M11: Este proyecto de los individuales para bandejas lo está impulsando la rectoria de la universidad como parte de ¨awarness¨ en lugares externos a UM. Todavia no se tiene claridad el número completo de ejemplares a realizar. Se ingresa el pedido para darle trazabilidad.
A12: 11 | B12: 46182.603 | C12: 46182.617 | D12: Rectoria - Comunicaciones y Mercadeo | E12: Camilo Robledo | F12: Coordinador Comunicaciones | G12: coordinadordecontenidos@unimetro.edu.co | H12: 46185 | I12: Volantes de programas académicos Pregado- Medicina - Nutrición y Dietética | J12: Volantes | K12: 3000 | L12: 46295 | M12: Los volantes de promoción de los programas académicos se imprimen con policromia completa. Por lo cual require por volante 4 planchas. El departamento de Diseño y Comunicaciones está en proceso de elaboración del diseño.
A13: 12 | B13: 46182.622 | C13: 46182.625 | D13: Rectoria - Comunicaciones y Mercadeo | E13: Camilo Robledo | F13: Coordinador Comunicaciones | G13: coordinadordecontenidos@unimetro.edu.co | H13: 46185 | I13: Volante progamas Pregrado - Bacteriología-Enfermeria-Fisioterapia- Trabajo Social | J13: Volantes | K13: 4000 | L13: 46295 | M13: De cada programa se requieren 1000 volantes aproximadamente en policromia
... A29: 28 | B29: 46297.648 | C29: 46297.649 | D29: Vicerrectoria - Direccion de bienestar universitario | E29: Katty Aguas Gamarra | F29: Coordinadora de Desarrollo Humano | G29: desarrollohumano@unimetro.edu.co | H29: 46300 | I29: Mini Agendas | J29: Mini Agendas o Libretas | K29: 60 | L29: 46314 | M29: 60 mini agendas color rosa con un diseño simple.

Sheet 02_Base_Solicitudes
A1: Id Forms | B1: Fecha recepción | C1: Fecha solicitud | D1: Dependencia | E1: Solicitante | F1: Cargo | G1: Correo | H1: Nombre trabajo | I1: Tipo trabajo | J1: Cantidad | K1: Fecha requerida | L1: Comentarios solicitud | M1: Prioridad | N1: Estado solicitud | O1: Info completa | P1: Días SLA | Q1: Alerta SLA | R1: Número OT | S1: Generar OT | T1: Observaciones validación
A2: =IF('01_Forms_Raw'!A2="","",'01_Forms_Raw'!A2) -> 1 | B2: =IF('01_Forms_Raw'!B2="","",'01_Forms_Raw'!B2) -> 46164.682 | C2: =IF('01_Forms_Raw'!H2="","",'01_Forms_Raw'!H2) -> 46185 | D2: =IF('01_Forms_Raw'!D2="","",'01_Forms_Raw'!D2) -> Rectoria - Comunicaciones y Mercadeo | E2: =IF('01_Forms_Raw'!E2="","",'01_Forms_Raw'!E2) -> Camilo Robledo | F2: =IF('01_Forms_Raw'!F2="","",'01_Forms_Raw'!F2) -> Coordinador Contenido | G2: =IF('01_Forms_Raw'!G2="","",'01_Forms_Raw'!G2) -> coordinadordecontenidos@unimetro.edu.co | H2: =IF('01_Forms_Raw'!I2="","",'01_Forms_Raw'!I2) -> Miniblocks - Mercadeo / pieza promocional unimetro | I2: =IF('01_Forms_Raw'!J2="","",'01_Forms_Raw'!J2) -> MiniBlocks | J2: =IF('01_Forms_Raw'!K2="","",VALUE('01_Forms_Raw'!K2)) -> 750 | K2: =IF('01_Forms_Raw'!L2="","",'01_Forms_Raw'!L2) -> 46233 | L2: =IF('01_Forms_Raw'!M2="","",'01_Forms_Raw'!M2) -> Mini Blocks pedido de Vicerrectoria. Se entregan 50 unidades a Julio Higgins para campaña mercadeo del Dpto de Diseño y Comunicaciones. El resto de la producción se entregará a Rectoría | M2: Normal | N2: Aprobada para OT | O2: =IF(A2="","",IF(AND(D2<>"",E2<>"",H2<>"",I2<>"",J2<>"",K2<>""),"Completa","Incompleta")) -> Completa | P2: =IF(A2="","",K2-C2) -> 48 | Q2: =IF(A2="","",IF(P2<3,"Riesgo SLA",IF(P2<7,"Corto","OK"))) -> OK | R2: =IF(A2="","","OT-UM-"&TEXT(C2,"yyyymm")&"-"&TEXT(A2,"000")) -> OT-UM-202606-001 | S2: =IF(A2="","",IF(O2="Completa","Sí","No")) -> Sí | T2: =IF(A2="","",IF(O2="Completa","Lista para OT","Completar brief antes de pasar a diseño")) -> Lista para OT
A3: =IF('01_Forms_Raw'!A3="","",'01_Forms_Raw'!A3) -> 2 | B3: =IF('01_Forms_Raw'!B3="","",'01_Forms_Raw'!B3) -> 46164.686 | C3: =IF('01_Forms_Raw'!H3="","",'01_Forms_Raw'!H3) -> 46185 | D3: =IF('01_Forms_Raw'!D3="","",'01_Forms_Raw'!D3) -> Rectoria - Comunicaciones y Mercadeo | E3: =IF('01_Forms_Raw'!E3="","",'01_Forms_Raw'!E3) -> Camilo Robledo | F3: =IF('01_Forms_Raw'!F3="","",'01_Forms_Raw'!F3) -> Coordinador Comunicaciones | G3: =IF('01_Forms_Raw'!G3="","",'01_Forms_Raw'!G3) -> coordinadordecontenidos@unimetro.edu.co | H3: =IF('01_Forms_Raw'!I3="","",'01_Forms_Raw'!I3) -> Memos - pieza de mercadeo para el area de comunicaciones | I3: =IF('01_Forms_Raw'!J3="","",'01_Forms_Raw'!J3) -> Memos | J3: =IF('01_Forms_Raw'!K3="","",VALUE('01_Forms_Raw'!K3)) -> 570 | K3: =IF('01_Forms_Raw'!L3="","",'01_Forms_Raw'!L3) -> 46310 | L3: =IF('01_Forms_Raw'!M3="","",'01_Forms_Raw'!M3) -> Mini Memos pedido de Vicerrectoria. Se entregan 50 unidades a Julio Higgins para campaña mercadeo del Dpto de Diseño y Comunicaciones | M3: Normal | N3: Aprobada para OT | O3: =IF(A3="","",IF(AND(D3<>"",E3<>"",H3<>"",I3<>"",J3<>"",K3<>""),"Completa","Incompleta")) -> Completa | P3: =IF(A3="","",K3-C3) -> 125 | Q3: =IF(A3="","",IF(P3<3,"Riesgo SLA",IF(P3<7,"Corto","OK"))) -> OK | R3: =IF(A3="","","OT-UM-"&TEXT(C3,"yyyymm")&"-"&TEXT(A3,"000")) -> OT-UM-202606-002 | S3: =IF(A3="","",IF(O3="Completa","Sí","No")) -> Sí | T3: =IF(A3="","",IF(O3="Completa","Lista para OT","Completar brief antes de pasar a diseño")) -> Lista para OT
A4: =IF('01_Forms_Raw'!A4="","",'01_Forms_Raw'!A4) -> 3 | B4: =IF('01_Forms_Raw'!B4="","",'01_Forms_Raw'!B4) -> 46164.69 | C4: =IF('01_Forms_Raw'!H4="","",'01_Forms_Raw'!H4) -> 46160 | D4: =IF('01_Forms_Raw'!D4="","",'01_Forms_Raw'!D4) -> Vicerrectoria | E4: =IF('01_Forms_Raw'!E4="","",'01_Forms_Raw'!E4) -> Jose Luis Castro Guerra | F4: =IF('01_Forms_Raw'!F4="","",'01_Forms_Raw'!F4) -> Vicerrector | G4: =IF('01_Forms_Raw'!G4="","",'01_Forms_Raw'!G4) -> vice-rectoria@unimetro.edu.co | H4: =IF('01_Forms_Raw'!I4="","",'01_Forms_Raw'!I4) -> Agendas - Material interno y de distribución externa para segundo semestre 2026 | I4: =IF('01_Forms_Raw'!J4="","",'01_Forms_Raw'!J4) -> Agendas | J4: =IF('01_Forms_Raw'!K4="","",VALUE('01_Forms_Raw'!K4)) -> 500 | K4: =IF('01_Forms_Raw'!L4="","",'01_Forms_Raw'!L4) -> 46230 | L4: =IF('01_Forms_Raw'!M4="","",'01_Forms_Raw'!M4) -> Material de la Agendas ya se adquirió. Al 11 de Junio la planchas están en proceso de elaboración por proveedor. Se requiere tecnico empastador para apoyar con el ensamble de las agendas | M4: Normal | N4: Aprobada para OT | O4: =IF(A4="","",IF(AND(D4<>"",E4<>"",H4<>"",I4<>"",J4<>"",K4<>""),"Completa","Incompleta")) -> Completa | P4: =IF(A4="","",K4-C4) -> 70 | Q4: =IF(A4="","",IF(P4<3,"Riesgo SLA",IF(P4<7,"Corto","OK"))) -> OK | R4: =IF(A4="","","OT-UM-"&TEXT(C4,"yyyymm")&"-"&TEXT(A4,"000")) -> OT-UM-202605-003 | S4: =IF(A4="","",IF(O4="Completa","Sí","No")) -> Sí | T4: =IF(A4="","",IF(O4="Completa","Lista para OT","Completar brief antes de pasar a diseño")) -> Lista para OT
A5: =IF('01_Forms_Raw'!A5="","",'01_Forms_Raw'!A5) -> 4 | B5: =IF('01_Forms_Raw'!B5="","",'01_Forms_Raw'!B5) -> 46164.704 | C5: =IF('01_Forms_Raw'!H5="","",'01_Forms_Raw'!H5) -> 46254 | D5: =IF('01_Forms_Raw'!D5="","",'01_Forms_Raw'!D5) -> Vicerrectoria | E5: =IF('01_Forms_Raw'!E5="","",'01_Forms_Raw'!E5) -> Jose Luis Castro | F5: =IF('01_Forms_Raw'!F5="","",'01_Forms_Raw'!F5) -> Vicerrector | G5: =IF('01_Forms_Raw'!G5="","",'01_Forms_Raw'!G5) -> vice-rectoria@unimetro.edu.co | H5: =IF('01_Forms_Raw'!I5="","",'01_Forms_Raw'!I5) -> Abanicos - Material de promoción de la universidad | I5: =IF('01_Forms_Raw'!J5="","",'01_Forms_Raw'!J5) -> Abanicos | J5: =IF('01_Forms_Raw'!K5="","",VALUE('01_Forms_Raw'!K5)) -> 1500 | K5: =IF('01_Forms_Raw'!L5="","",'01_Forms_Raw'!L5) -> 46324 | L5: =IF('01_Forms_Raw'!M5="","",'01_Forms_Raw'!M5) -> Los abanicos hacen parte de un material de promoción. Todavía no tiene aprobación de Rectoría | M5: Normal | N5: Recibida | O5: =IF(A5="","",IF(AND(D5<>"",E5<>"",H5<>"",I5<>"",J5<>"",K5<>""),"Completa","Incompleta")) -> Completa | P5: =IF(A5="","",K5-C5) -> 70 | Q5: =IF(A5="","",IF(P5<3,"Riesgo SLA",IF(P5<7,"Corto","OK"))) -> OK | R5: =IF(A5="","","OT-UM-"&TEXT(C5,"yyyymm")&"-"&TEXT(A5,"000")) -> OT-UM-202608-004 | S5: =IF(A5="","",IF(O5="Completa","Sí","No")) -> Sí | T5: =IF(A5="","",IF(O5="Completa","Lista para OT","Completar brief antes de pasar a diseño")) -> Lista para OT
A6: =IF('01_Forms_Raw'!A6="","",'01_Forms_Raw'!A6) -> 5 | B6: =IF('01_Forms_Raw'!B6="","",'01_Forms_Raw'!B6) -> 46167.394 | C6: =IF('01_Forms_Raw'!H6="","",'01_Forms_Raw'!H6) -> 46153 | D6: =IF('01_Forms_Raw'!D6="","",'01_Forms_Raw'!D6) -> Vicerrectoria | E6: =IF('01_Forms_Raw'!E6="","",'01_Forms_Raw'!E6) -> Indira Luz de la Rosa | F6: =IF('01_Forms_Raw'!F6="","",'01_Forms_Raw'!F6) -> Asistente Vicerectoria | G6: =IF('01_Forms_Raw'!G6="","",'01_Forms_Raw'!G6) -> idelarosa@unimetro.edu.co | H6: =IF('01_Forms_Raw'!I6="","",'01_Forms_Raw'!I6) -> Actas de Grado | I6: =IF('01_Forms_Raw'!J6="","",'01_Forms_Raw'!J6) -> Actas de grado | J6: =IF('01_Forms_Raw'!K6="","",VALUE('01_Forms_Raw'!K6)) -> 1000 | K6: =IF('01_Forms_Raw'!L6="","",'01_Forms_Raw'!L6) -> 46184 | L6: =IF('01_Forms_Raw'!M6="","",'01_Forms_Raw'!M6) -> Cotizar papel Opalina . Sr Julio Rivera consiguió la cotización de 150 pliegos en Dipaca - distribuidora papelera del caribe. | M6: Normal | N6: Aprobada para OT | O6: =IF(A6="","",IF(AND(D6<>"",E6<>"",H6<>"",I6<>"",J6<>"",K6<>""),"Completa","Incompleta")) -> Completa | P6: =IF(A6="","",K6-C6) -> 31 | Q6: =IF(A6="","",IF(P6<3,"Riesgo SLA",IF(P6<7,"Corto","OK"))) -> OK | R6: =IF(A6="","","OT-UM-"&TEXT(C6,"yyyymm")&"-"&TEXT(A6,"000")) -> OT-UM-202605-005 | S6: =IF(A6="","",IF(O6="Completa","Sí","No")) -> Sí | T6: =IF(A6="","",IF(O6="Completa","Lista para OT","Completar brief antes de pasar a diseño")) -> Lista para OT
A7: =IF('01_Forms_Raw'!A7="","",'01_Forms_Raw'!A7) -> 6 | B7: =IF('01_Forms_Raw'!B7="","",'01_Forms_Raw'!B7) -> 46167.398 | C7: =IF('01_Forms_Raw'!H7="","",'01_Forms_Raw'!H7) -> 46121 | D7: =IF('01_Forms_Raw'!D7="","",'01_Forms_Raw'!D7) -> Vicerrectoria - Biblioteca | E7: =IF('01_Forms_Raw'!E7="","",'01_Forms_Raw'!E7) -> Yarima Medrano Nazzer | F7: =IF('01_Forms_Raw'!F7="","",'01_Forms_Raw'!F7) -> Directora Biblioteca | G7: =IF('01_Forms_Raw'!G7="","",'01_Forms_Raw'!G7) -> directorabiblioteca@unimetro.edu.co | H7: =IF('01_Forms_Raw'!I7="","",'01_Forms_Raw'!I7) -> Tarjetas de Prestamo | I7: =IF('01_Forms_Raw'!J7="","",'01_Forms_Raw'!J7) -> Tarjetas Prestamo Biblioteca | J7: =IF('01_Forms_Raw'!K7="","",VALUE('01_Forms_Raw'!K7)) -> 5000 | K7: =IF('01_Forms_Raw'!L7="","",'01_Forms_Raw'!L7) -> 46259 | L7: =IF('01_Forms_Raw'!M7="","",'01_Forms_Raw'!M7) -> Esta solicitud tuvo una demora causada por el material que llego solo hasta el 4 de mayo. | M7: Normal | N7: Aprobada para OT | O7: =IF(A7="","",IF(AND(D7<>"",E7<>"",H7<>"",I7<>"",J7<>"",K7<>""),"Completa","Incompleta")) -> Completa | P7: =IF(A7="","",K7-C7) -> 138 | Q7: =IF(A7="","",IF(P7<3,"Riesgo SLA",IF(P7<7,"Corto","OK"))) -> OK | R7: =IF(A7="","","OT-UM-"&TEXT(C7,"yyyymm")&"-"&TEXT(A7,"000")) -> OT-UM-202604-006 | S7: =IF(A7="","",IF(O7="Completa","Sí","No")) -> Sí | T7: =IF(A7="","",IF(O7="Completa","Lista para OT","Completar brief antes de pasar a diseño")) -> Lista para OT
A8: =IF('01_Forms_Raw'!A8="","",'01_Forms_Raw'!A8) -> 7 | B8: =IF('01_Forms_Raw'!B8="","",'01_Forms_Raw'!B8) -> 46167.41 | C8: =IF('01_Forms_Raw'!H8="","",'01_Forms_Raw'!H8) -> 46121 | D8: =IF('01_Forms_Raw'!D8="","",'01_Forms_Raw'!D8) -> Vicerrectoria - Biblioteca | E8: =IF('01_Forms_Raw'!E8="","",'01_Forms_Raw'!E8) -> Yarima Medrano Nazzer | F8: =IF('01_Forms_Raw'!F8="","",'01_Forms_Raw'!F8) -> Directora Biblioteca | G8: =IF('01_Forms_Raw'!G8="","",'01_Forms_Raw'!G8) -> directorabiblioteca@unimetro.edu.co | H8: =IF('01_Forms_Raw'!I8="","",'01_Forms_Raw'!I8) -> Bolsillos de tarjeta de préstamo | I8: =IF('01_Forms_Raw'!J8="","",'01_Forms_Raw'!J8) -> Bolsillos de tarjeta de préstamo | J8: =IF('01_Forms_Raw'!K8="","",VALUE('01_Forms_Raw'!K8)) -> 2000 | K8: =IF('01_Forms_Raw'!L8="","",'01_Forms_Raw'!L8) -> 46259 | L8: =IF('01_Forms_Raw'!M8="","",'01_Forms_Raw'!M8) -> Material pedido en Febrero solo se recepcionó hasta inicios de Mayo. | M8: Normal | N8: Aprobada para OT | O8: =IF(A8="","",IF(AND(D8<>"",E8<>"",H8<>"",I8<>"",J8<>"",K8<>""),"Completa","Incompleta")) -> Completa | P8: =IF(A8="","",K8-C8) -> 138 | Q8: =IF(A8="","",IF(P8<3,"Riesgo SLA",IF(P8<7,"Corto","OK"))) -> OK | R8: =IF(A8="","","OT-UM-"&TEXT(C8,"yyyymm")&"-"&TEXT(A8,"000")) -> OT-UM-202604-007 | S8: =IF(A8="","",IF(O8="Completa","Sí","No")) -> Sí | T8: =IF(A8="","",IF(O8="Completa","Lista para OT","Completar brief antes de pasar a diseño")) -> Lista para OT
A9: =IF('01_Forms_Raw'!A9="","",'01_Forms_Raw'!A9) -> 8 | B9: =IF('01_Forms_Raw'!B9="","",'01_Forms_Raw'!B9) -> 46167.413 | C9: =IF('01_Forms_Raw'!H9="","",'01_Forms_Raw'!H9) -> 46121 | D9: =IF('01_Forms_Raw'!D9="","",'01_Forms_Raw'!D9) -> Vicerrectoria - Biblioteca | E9: =IF('01_Forms_Raw'!E9="","",'01_Forms_Raw'!E9) -> Yarima Medrano Nazzer | F9: =IF('01_Forms_Raw'!F9="","",'01_Forms_Raw'!F9) -> Directora Biblioteca | G9: =IF('01_Forms_Raw'!G9="","",'01_Forms_Raw'!G9) -> directorabiblioteca@unimetro.edu.co | H9: =IF('01_Forms_Raw'!I9="","",'01_Forms_Raw'!I9) -> Adhesivos de Colores para categorizar grupos de Libros | I9: =IF('01_Forms_Raw'!J9="","",'01_Forms_Raw'!J9) -> Adhesivos de Colores | J9: =IF('01_Forms_Raw'!K9="","",VALUE('01_Forms_Raw'!K9)) -> 1300 | K9: =IF('01_Forms_Raw'!L9="","",'01_Forms_Raw'!L9) -> 46155 | L9: =IF('01_Forms_Raw'!M9="","",'01_Forms_Raw'!M9) -> Se realizaran adhesivos tamaño carta Amarillo, verde, rosado, gris, azul - 500/200/200/200/200. Se entregaron el 11 de Mayo | M9: Normal | N9: Aprobada para OT | O9: =IF(A9="","",IF(AND(D9<>"",E9<>"",H9<>"",I9<>"",J9<>"",K9<>""),"Completa","Incompleta")) -> Completa | P9: =IF(A9="","",K9-C9) -> 34 | Q9: =IF(A9="","",IF(P9<3,"Riesgo SLA",IF(P9<7,"Corto","OK"))) -> OK | R9: =IF(A9="","","OT-UM-"&TEXT(C9,"yyyymm")&"-"&TEXT(A9,"000")) -> OT-UM-202604-008 | S9: =IF(A9="","",IF(O9="Completa","Sí","No")) -> Sí | T9: =IF(A9="","",IF(O9="Completa","Lista para OT","Completar brief antes de pasar a diseño")) -> Lista para OT
A10: =IF('01_Forms_Raw'!A10="","",'01_Forms_Raw'!A10) -> 9 | B10: =IF('01_Forms_Raw'!B10="","",'01_Forms_Raw'!B10) -> 46177.929 | C10: =IF('01_Forms_Raw'!H10="","",'01_Forms_Raw'!H10) -> 46170 | D10: =IF('01_Forms_Raw'!D10="","",'01_Forms_Raw'!D10) -> Vicerrectoria - Direccion Administrativa | E10: =IF('01_Forms_Raw'!E10="","",'01_Forms_Raw'!E10) -> Elio Ortiz | F10: =IF('01_Forms_Raw'!F10="","",'01_Forms_Raw'!F10) -> Director Administrativo | G10: =IF('01_Forms_Raw'!G10="","",'01_Forms_Raw'!G10) -> eortizg@unimetro.edu.co | H10: Hojas membretadas uso institucional para varias dependencias | I10: =IF('01_Forms_Raw'!J10="","",'01_Forms_Raw'!J10) -> Hojas Membreteadas | J10: =IF('01_Forms_Raw'!K10="","",VALUE('01_Forms_Raw'!K10)) -> 5000 | K10: =IF('01_Forms_Raw'!L10="","",'01_Forms_Raw'!L10) -> 46249 | L10: =IF('01_Forms_Raw'!M10="","",'01_Forms_Raw'!M10) -> Se estima que para finalesde junio se debe tener la hojas membretadas para el uso en varias dependencias. | M10: Normal | N10: Aprobada para OT | O10: =IF(A10="","",IF(AND(D10<>"",E10<>"",H10<>"",I10<>"",J10<>"",K10<>""),"Completa","Incompleta")) -> Completa | P10: =IF(A10="","",K10-C10) -> 79 | Q10: =IF(A10="","",IF(P10<3,"Riesgo SLA",IF(P10<7,"Corto","OK"))) -> OK | R10: =IF(A10="","","OT-UM-"&TEXT(C10,"yyyymm")&"-"&TEXT(A10,"000")) -> OT-UM-202605-009 | S10: =IF(A10="","",IF(O10="Completa","Sí","No")) -> Sí | T10: =IF(A10="","",IF(O10="Completa","Lista para OT","Completar brief antes de pasar a diseño")) -> Lista para OT
A11: =IF('01_Forms_Raw'!A11="","",'01_Forms_Raw'!A11) -> 10 | B11: =IF('01_Forms_Raw'!B11="","",'01_Forms_Raw'!B11) -> 46178.649 | C11: =IF('01_Forms_Raw'!H11="","",'01_Forms_Raw'!H11) -> 46155 | D11: =IF('01_Forms_Raw'!D11="","",'01_Forms_Raw'!D11) -> Rectoria - Alta consejeria | E11: =IF('01_Forms_Raw'!E11="","",'01_Forms_Raw'!E11) -> Julian Ramirez | F11: =IF('01_Forms_Raw'!F11="","",'01_Forms_Raw'!F11) -> Coordinador Imprenta UM | G11: =IF('01_Forms_Raw'!G11="","",'01_Forms_Raw'!G11) -> jramirezo@unimetro.edu.co | H11: =IF('01_Forms_Raw'!I11="","",'01_Forms_Raw'!I11) -> Individuales para bandejas de plazoleta de comidas | I11: =IF('01_Forms_Raw'!J11="","",'01_Forms_Raw'!J11) -> Individuales para bandejas | J11: =IF('01_Forms_Raw'!K11="","",VALUE('01_Forms_Raw'!K11)) -> 3600 | K11: =IF('01_Forms_Raw'!L11="","",'01_Forms_Raw'!L11) -> 46254 | L11: =IF('01_Forms_Raw'!M11="","",'01_Forms_Raw'!M11) -> Este proyecto de los individuales para bandejas lo está impulsando la rectoria de la universidad como parte de ¨awarness¨ en lugares externos a UM. Todavia no se tiene claridad el número completo de ejemplares a realizar. Se ingresa el pedido para darle trazabilidad. | M11: Normal | N11: Aprobada para OT | O11: =IF(A11="","",IF(AND(D11<>"",E11<>"",H11<>"",I11<>"",J11<>"",K11<>""),"Completa","Incompleta")) -> Completa | P11: =IF(A11="","",K11-C11) -> 99 | Q11: =IF(A11="","",IF(P11<3,"Riesgo SLA",IF(P11<7,"Corto","OK"))) -> OK | R11: =IF(A11="","","OT-UM-"&TEXT(C11,"yyyymm")&"-"&TEXT(A11,"000")) -> OT-UM-202605-010 | S11: =IF(A11="","",IF(O11="Completa","Sí","No")) -> Sí | T11: =IF(A11="","",IF(O11="Completa","Lista para OT","Completar brief antes de pasar a diseño")) -> Lista para OT
A12: =IF('01_Forms_Raw'!A12="","",'01_Forms_Raw'!A12) -> 11 | B12: =IF('01_Forms_Raw'!B12="","",'01_Forms_Raw'!B12) -> 46182.603 | C12: =IF('01_Forms_Raw'!H12="","",'01_Forms_Raw'!H12) -> 46185 | D12: =IF('01_Forms_Raw'!D12="","",'01_Forms_Raw'!D12) -> Rectoria - Comunicaciones y Mercadeo | E12: =IF('01_Forms_Raw'!E12="","",'01_Forms_Raw'!E12) -> Camilo Robledo | F12: =IF('01_Forms_Raw'!F12="","",'01_Forms_Raw'!F12) -> Coordinador Comunicaciones | G12: =IF('01_Forms_Raw'!G12="","",'01_Forms_Raw'!G12) -> coordinadordecontenidos@unimetro.edu.co | H12: =IF('01_Forms_Raw'!I12="","",'01_Forms_Raw'!I12) -> Volantes de programas académicos Pregado- Medicina - Nutrición y Dietética | I12: =IF('01_Forms_Raw'!J12="","",'01_Forms_Raw'!J12) -> Volantes | J12: =IF('01_Forms_Raw'!K12="","",VALUE('01_Forms_Raw'!K12)) -> 3000 | K12: =IF('01_Forms_Raw'!L12="","",'01_Forms_Raw'!L12) -> 46295 | L12: =IF('01_Forms_Raw'!M12="","",'01_Forms_Raw'!M12) -> Los volantes de promoción de los programas académicos se imprimen con policromia completa. Por lo cual require por volante 4 planchas. El departamento de Diseño y Comunicaciones está en proceso de elaboración del diseño. | M12: Normal | N12: Recibida | O12: =IF(A12="","",IF(AND(D12<>"",E12<>"",H12<>"",I12<>"",J12<>"",K12<>""),"Completa","Incompleta")) -> Completa | P12: =IF(A12="","",K12-C12) -> 110 | Q12: =IF(A12="","",IF(P12<3,"Riesgo SLA",IF(P12<7,"Corto","OK"))) -> OK | R12: =IF(A12="","","OT-UM-"&TEXT(C12,"yyyymm")&"-"&TEXT(A12,"000")) -> OT-UM-202606-011 | S12: =IF(A12="","",IF(O12="Completa","Sí","No")) -> Sí | T12: =IF(A12="","",IF(O12="Completa","Lista para OT","Completar brief antes de pasar a diseño")) -> Lista para OT
A13: =IF('01_Forms_Raw'!A13="","",'01_Forms_Raw'!A13) -> 12 | B13: =IF('01_Forms_Raw'!B13="","",'01_Forms_Raw'!B13) -> 46182.622 | C13: =IF('01_Forms_Raw'!H13="","",'01_Forms_Raw'!H13) -> 46185 | D13: =IF('01_Forms_Raw'!D13="","",'01_Forms_Raw'!D13) -> Rectoria - Comunicaciones y Mercadeo | E13: =IF('01_Forms_Raw'!E13="","",'01_Forms_Raw'!E13) -> Camilo Robledo | F13: =IF('01_Forms_Raw'!F13="","",'01_Forms_Raw'!F13) -> Coordinador Comunicaciones | G13: =IF('01_Forms_Raw'!G13="","",'01_Forms_Raw'!G13) -> coordinadordecontenidos@unimetro.edu.co | H13: =IF('01_Forms_Raw'!I13="","",'01_Forms_Raw'!I13) -> Volante progamas Pregrado - Bacteriología-Enfermeria-Fisioterapia- Trabajo Social | I13: =IF('01_Forms_Raw'!J13="","",'01_Forms_Raw'!J13) -> Volantes | J13: =IF('01_Forms_Raw'!K13="","",VALUE('01_Forms_Raw'!K13)) -> 4000 | K13: =IF('01_Forms_Raw'!L13="","",'01_Forms_Raw'!L13) -> 46295 | L13: =IF('01_Forms_Raw'!M13="","",'01_Forms_Raw'!M13) -> De cada programa se requieren 1000 volantes aproximadamente en policromia | M13: Normal | N13: Recibida | O13: =IF(A13="","",IF(AND(D13<>"",E13<>"",H13<>"",I13<>"",J13<>"",K13<>""),"Completa","Incompleta")) -> Completa | P13: =IF(A13="","",K13-C13) -> 110 | Q13: =IF(A13="","",IF(P13<3,"Riesgo SLA",IF(P13<7,"Corto","OK"))) -> OK | R13: =IF(A13="","","OT-UM-"&TEXT(C13,"yyyymm")&"-"&TEXT(A13,"000")) -> OT-UM-202606-012 | S13: =IF(A13="","",IF(O13="Completa","Sí","No")) -> Sí | T13: =IF(A13="","",IF(O13="Completa","Lista para OT","Completar brief antes de pasar a diseño")) -> Lista para OT
A14: =IF('01_Forms_Raw'!A14="","",'01_Forms_Raw'!A14) -> 13 | B14: =IF('01_Forms_Raw'!B14="","",'01_Forms_Raw'!B14) -> 46184.735 | C14: =IF('01_Forms_Raw'!H14="","",'01_Forms_Raw'!H14) -> 46185 | D14: =IF('01_Forms_Raw'!D14="","",'01_Forms_Raw'!D14) -> Rectoria - Comunicaciones y Mercadeo | E14: =IF('01_Forms_Raw'!E14="","",'01_Forms_Raw'!E14) -> Camilo Robledo | F14: =IF('01_Forms_Raw'!F14="","",'01_Forms_Raw'!F14) -> Coordinador Comunicaciones | G14: =IF('01_Forms_Raw'!G14="","",'01_Forms_Raw'!G14) -> coordinadordecontenidos@unimetro.edu.co | H14: =IF('01_Forms_Raw'!I14="","",'01_Forms_Raw'!I14) -> Volante programas pregrado - Odontología - Optometría - Psicología - Terapia Ocupacional | I14: =IF('01_Forms_Raw'!J14="","",'01_Forms_Raw'!J14) -> Volantes | J14: =IF('01_Forms_Raw'!K14="","",VALUE('01_Forms_Raw'!K14)) -> 4000 | K14: =IF('01_Forms_Raw'!L14="","",'01_Forms_Raw'!L14) -> 46295 | L14: =IF('01_Forms_Raw'!M14="","",'01_Forms_Raw'!M14) -> De cada programa se requieren 1000 volantes aproximadamente en policromia | M14: Normal | N14: Recibida | O14: =IF(A14="","",IF(AND(D14<>"",E14<>"",H14<>"",I14<>"",J14<>"",K14<>""),"Completa","Incompleta")) -> Completa | P14: =IF(A14="","",K14-C14) -> 110 | Q14: =IF(A14="","",IF(P14<3,"Riesgo SLA",IF(P14<7,"Corto","OK"))) -> OK | R14: =IF(A14="","","OT-UM-"&TEXT(C14,"yyyymm")&"-"&TEXT(A14,"000")) -> OT-UM-202606-013 | S14: =IF(A14="","",IF(O14="Completa","Sí","No")) -> Sí | T14: =IF(A14="","",IF(O14="Completa","Lista para OT","Completar brief antes de pasar a diseño")) -> Lista para OT
A15: =IF('01_Forms_Raw'!A15="","",'01_Forms_Raw'!A15) -> 14 | B15: =IF('01_Forms_Raw'!B15="","",'01_Forms_Raw'!B15) -> 46164.69 | C15: =IF('01_Forms_Raw'!H15="","",'01_Forms_Raw'!H15) -> 46200 | D15: =IF('01_Forms_Raw'!D15="","",'01_Forms_Raw'!D15) -> Vicerrectoria | E15: =IF('01_Forms_Raw'!E15="","",'01_Forms_Raw'!E15) -> Jose Luis Castro Guerra | F15: =IF('01_Forms_Raw'!F15="","",'01_Forms_Raw'!F15) -> Vicerrector | G15: =IF('01_Forms_Raw'!G15="","",'01_Forms_Raw'!G15) -> vice-rectoria@unimetro.edu.co | H15: =IF('01_Forms_Raw'!I15="","",'01_Forms_Raw'!I15) -> Agendas - 2ndo lote de 500 unidades para 30Sep | I15: =IF('01_Forms_Raw'!J15="","",'01_Forms_Raw'!J15) -> Agendas | J15: =IF('01_Forms_Raw'!K15="","",VALUE('01_Forms_Raw'!K15)) -> 500 | K15: =IF('01_Forms_Raw'!L15="","",'01_Forms_Raw'!L15) -> 46310 | L15: =IF('01_Forms_Raw'!M15="","",'01_Forms_Raw'!M15) -> Se divide el pedido inicial de1000 agendas en 2 etapas. 500 para inicio 2nd semestre de 2026 y las otras 500 para finales de Noviembre para suplir la necesidad de 1er semestre de 2027 | M15: Programado | N15: Aprobada para OT | O15: =IF(A15="","",IF(AND(D15<>"",E15<>"",H15<>"",I15<>"",J15<>"",K15<>""),"Completa","Incompleta")) -> Completa | P15: =IF(A15="","",K15-C15) -> 110 | Q15: =IF(A15="","",IF(P15<3,"Riesgo SLA",IF(P15<7,"Corto","OK"))) -> OK | R15: =IF(A15="","","OT-UM-"&TEXT(C15,"yyyymm")&"-"&TEXT(A15,"000")) -> OT-UM-202606-014 | S15: =IF(A15="","",IF(O15="Completa","Sí","No")) -> Sí | T15: =IF(A15="","",IF(O15="Completa","Lista para OT","Completar brief antes de pasar a diseño")) -> Lista para OT
A16: =IF('01_Forms_Raw'!A16="","",'01_Forms_Raw'!A16) -> 15 | B16: =IF('01_Forms_Raw'!B16="","",'01_Forms_Raw'!B16) -> 46233.622 | C16: =IF('01_Forms_Raw'!H16="","",'01_Forms_Raw'!H16) -> 46267 | D16: =IF('01_Forms_Raw'!D16="","",'01_Forms_Raw'!D16) -> Rectoria - Alta consejeria | E16: =IF('01_Forms_Raw'!E16="","",'01_Forms_Raw'!E16) -> Camilo Robledo | F16: =IF('01_Forms_Raw'!F16="","",'01_Forms_Raw'!F16) -> Coordinador Comunicaciones | G16: =IF('01_Forms_Raw'!G16="","",'01_Forms_Raw'!G16) -> coordinadordecontenidos@unimetro.edu.co | H16: =IF('01_Forms_Raw'!I16="","",'01_Forms_Raw'!I16) -> Calendario 2027 | I16: =IF('01_Forms_Raw'!J16="","",'01_Forms_Raw'!J16) -> Calendarios | J16: =IF('01_Forms_Raw'!K16="","",VALUE('01_Forms_Raw'!K16)) -> 4000 | K16: =IF('01_Forms_Raw'!L16="","",'01_Forms_Raw'!L16) -> 46326 | L16: =IF('01_Forms_Raw'!M16="","",'01_Forms_Raw'!M16) -> Los Calendarios hacen parte la marca instutucional de la universidad. El diseño debe iniciarse desde 1ero de Agosto para que la Imprenta inicie la impresión a mas tardar el 1ero de Octubre. | M16: Programado | N16: Recibida | O16: =IF(A16="","",IF(AND(D16<>"",E16<>"",H16<>"",I16<>"",J16<>"",K16<>""),"Completa","Incompleta")) -> Completa | P16: =IF(A16="","",K16-C16) -> 59 | Q16: =IF(A16="","",IF(P16<3,"Riesgo SLA",IF(P16<7,"Corto","OK"))) -> OK | R16: =IF(A16="","","OT-UM-"&TEXT(C16,"yyyymm")&"-"&TEXT(A16,"000")) -> OT-UM-202609-015 | S16: =IF(A16="","",IF(O16="Completa","Sí","No")) -> Sí | T16: =IF(A16="","",IF(O16="Completa","Lista para OT","Completar brief antes de pasar a diseño")) -> Lista para OT
A17: =IF('01_Forms_Raw'!A17="","",'01_Forms_Raw'!A17) -> 16 | B17: =IF('01_Forms_Raw'!B17="","",'01_Forms_Raw'!B17) -> 46238 | C17: =IF('01_Forms_Raw'!H17="","",'01_Forms_Raw'!H17) -> 46238 | D17: =IF('01_Forms_Raw'!D17="","",'01_Forms_Raw'!D17) -> Vicerrectoria - Direccion de bienestar universitario | E17: =IF('01_Forms_Raw'!E17="","",'01_Forms_Raw'!E17) -> Katty Aguas Gamarra | F17: =IF('01_Forms_Raw'!F17="","",'01_Forms_Raw'!F17) -> Coordinadora de Desarrollo Humano | G17: =IF('01_Forms_Raw'!G17="","",'01_Forms_Raw'!G17) -> desarrollohumano@unimetro.edu.co | H17: =IF('01_Forms_Raw'!I17="","",'01_Forms_Raw'!I17) -> ACTUALIZACION DE FOLLETO DE SALUD MENTAL | I17: =IF('01_Forms_Raw'!J17="","",'01_Forms_Raw'!J17) -> Folletos | J17: =IF('01_Forms_Raw'!K17="","",VALUE('01_Forms_Raw'!K17)) -> 2000 | K17: =IF('01_Forms_Raw'!L17="","",'01_Forms_Raw'!L17) -> 46275 | L17: =IF('01_Forms_Raw'!M17="","",'01_Forms_Raw'!M17) -> El diseño fue enviado a su correo institucional. | M17: Programado | N17: Validada | O17: =IF(A17="","",IF(AND(D17<>"",E17<>"",H17<>"",I17<>"",J17<>"",K17<>""),"Completa","Incompleta")) -> Completa | P17: =IF(A17="","",K17-C17) -> 37 | Q17: =IF(A17="","",IF(P17<3,"Riesgo SLA",IF(P17<7,"Corto","OK"))) -> OK | R17: =IF(A17="","","OT-UM-"&TEXT(C17,"yyyymm")&"-"&TEXT(A17,"000")) -> OT-UM-202608-016 | S17: =IF(A17="","",IF(O17="Completa","Sí","No")) -> Sí | T17: =IF(A17="","",IF(O17="Completa","Lista para OT","Completar brief antes de pasar a diseño")) -> Lista para OT
A18: =IF('01_Forms_Raw'!A18="","",'01_Forms_Raw'!A18) -> 17 | B18: =IF('01_Forms_Raw'!B18="","",'01_Forms_Raw'!B18) -> 46238 | C18: =IF('01_Forms_Raw'!H18="","",'01_Forms_Raw'!H18) -> 46238 | D18: =IF('01_Forms_Raw'!D18="","",'01_Forms_Raw'!D18) -> Rectoria - Comunicaciones y Mercadeo | E18: =IF('01_Forms_Raw'!E18="","",'01_Forms_Raw'!E18) -> Julio Higgins | F18: =IF('01_Forms_Raw'!F18="","",'01_Forms_Raw'!F18) -> Relaciones Publicas | G18: =IF('01_Forms_Raw'!G18="","",'01_Forms_Raw'!G18) -> relacionespublicas@unimetro.edu.co | H18: =IF('01_Forms_Raw'!I18="","",'01_Forms_Raw'!I18) -> Volantes Pregrado y Postgrado Unimetro | I18: =IF('01_Forms_Raw'!J18="","",'01_Forms_Raw'!J18) -> Volantes | J18: =IF('01_Forms_Raw'!K18="","",VALUE('01_Forms_Raw'!K18)) -> 500 | K18: =IF('01_Forms_Raw'!L18="","",'01_Forms_Raw'!L18) -> 46239 | L18: =IF('01_Forms_Raw'!M18="","",'01_Forms_Raw'!M18) -> Se utilizará el diseño anterior que contaba con 10 programas de pre y post grado. Se recomienda al departamento de comunicaciones y mercadeo realizar un nuevo diseño para el próximo batch | M18: Urgente | N18: Aprobada para OT | O18: =IF(A18="","",IF(AND(D18<>"",E18<>"",H18<>"",I18<>"",J18<>"",K18<>""),"Completa","Incompleta")) -> Completa | P18: =IF(A18="","",K18-C18) -> 1 | Q18: =IF(A18="","",IF(P18<3,"Riesgo SLA",IF(P18<7,"Corto","OK"))) -> Riesgo SLA | R18: =IF(A18="","","OT-UM-"&TEXT(C18,"yyyymm")&"-"&TEXT(A18,"000")) -> OT-UM-202608-017 | S18: =IF(A18="","",IF(O18="Completa","Sí","No")) -> Sí | T18: =IF(A18="","",IF(O18="Completa","Lista para OT","Completar brief antes de pasar a diseño")) -> Lista para OT
A19: =IF('01_Forms_Raw'!A19="","",'01_Forms_Raw'!A19) -> 18 | B19: =IF('01_Forms_Raw'!B19="","",'01_Forms_Raw'!B19) -> 46238 | C19: =IF('01_Forms_Raw'!H19="","",'01_Forms_Raw'!H19) -> 46238 | D19: =IF('01_Forms_Raw'!D19="","",'01_Forms_Raw'!D19) -> Vicerrectoria - Direccion de bienestar universitario | E19: =IF('01_Forms_Raw'!E19="","",'01_Forms_Raw'!E19) -> Katty Aguas Gamarra | F19: =IF('01_Forms_Raw'!F19="","",'01_Forms_Raw'!F19) -> Coordinadora de Desarrollo Humano | G19: =IF('01_Forms_Raw'!G19="","",'01_Forms_Raw'!G19) -> desarrollohumano@unimetro.edu.co | H19: =IF('01_Forms_Raw'!I19="","",'01_Forms_Raw'!I19) -> ACTUALIZACION DE FOLLETO DE LOS SERVICIOS DE BIENESTAR UNIVERSITARIO | I19: =IF('01_Forms_Raw'!J19="","",'01_Forms_Raw'!J19) -> Folletos | J19: =IF('01_Forms_Raw'!K19="","",VALUE('01_Forms_Raw'!K19)) -> 2000 | K19: =IF('01_Forms_Raw'!L19="","",'01_Forms_Raw'!L19) -> 46296 | L19: =IF('01_Forms_Raw'!M19="","",'01_Forms_Raw'!M19) -> El diseño fue enviado a su correo institucional. | M19: Programado | N19: Validada | O19: =IF(A19="","",IF(AND(D19<>"",E19<>"",H19<>"",I19<>"",J19<>"",K19<>""),"Completa","Incompleta")) -> Completa | P19: =IF(A19="","",K19-C19) -> 58 | Q19: =IF(A19="","",IF(P19<3,"Riesgo SLA",IF(P19<7,"Corto","OK"))) -> OK | R19: =IF(A19="","","OT-UM-"&TEXT(C19,"yyyymm")&"-"&TEXT(A19,"000")) -> OT-UM-202608-018 | S19: =IF(A19="","",IF(O19="Completa","Sí","No")) -> Sí | T19: =IF(A19="","",IF(O19="Completa","Lista para OT","Completar brief antes de pasar a diseño")) -> Lista para OT
A20: =IF('01_Forms_Raw'!A20="","",'01_Forms_Raw'!A20) -> 19 | B20: =IF('01_Forms_Raw'!B20="","",'01_Forms_Raw'!B20) -> 46245 | C20: =IF('01_Forms_Raw'!H20="","",'01_Forms_Raw'!H20) -> 46245 | D20: =IF('01_Forms_Raw'!D20="","",'01_Forms_Raw'!D20) -> Rectoria - Comunicaciones y Mercadeo | E20: =IF('01_Forms_Raw'!E20="","",'01_Forms_Raw'!E20) -> Julio Higgins | F20: =IF('01_Forms_Raw'!F20="","",'01_Forms_Raw'!F20) -> Relaciones Publicas | G20: =IF('01_Forms_Raw'!G20="","",'01_Forms_Raw'!G20) -> relacionespublicas@unimetro.edu.co | H20: =IF('01_Forms_Raw'!I20="","",'01_Forms_Raw'!I20) -> Volantes QR Pregrado y Postgrado Actualizado Unimetro | I20: =IF('01_Forms_Raw'!J20="","",'01_Forms_Raw'!J20) -> Volantes | J20: =IF('01_Forms_Raw'!K20="","",VALUE('01_Forms_Raw'!K20)) -> 2000 | K20: =IF('01_Forms_Raw'!L20="","",'01_Forms_Raw'!L20) -> 46295 | L20: =IF('01_Forms_Raw'!M20="","",'01_Forms_Raw'!M20) -> Se aprobó una nueva versión del volante infomativo de las carreras, Este volante informativo se requiere para todo el año, es decir, una buena cantidad de ejemplares se requieren. Para H2 se harán 3000 y se esperan complementar con los dedicados a cada programa | M20: Programado | N20: Aprobada para OT | O20: =IF(A20="","",IF(AND(D20<>"",E20<>"",H20<>"",I20<>"",J20<>"",K20<>""),"Completa","Incompleta")) -> Completa | P20: =IF(A20="","",K20-C20) -> 50 | Q20: =IF(A20="","",IF(P20<3,"Riesgo SLA",IF(P20<7,"Corto","OK"))) -> OK | R20: =IF(A20="","","OT-UM-"&TEXT(C20,"yyyymm")&"-"&TEXT(A20,"000")) -> OT-UM-202608-019 | S20: =IF(A20="","",IF(O20="Completa","Sí","No")) -> Sí | T20: =IF(A20="","",IF(O20="Completa","Lista para OT","Completar brief antes de pasar a diseño")) -> Lista para OT
A21: =IF('01_Forms_Raw'!A21="","",'01_Forms_Raw'!A21) -> 20 | B21: =IF('01_Forms_Raw'!B21="","",'01_Forms_Raw'!B21) -> 46259 | C21: =IF('01_Forms_Raw'!H21="","",'01_Forms_Raw'!H21) -> 46259 | D21: =IF('01_Forms_Raw'!D21="","",'01_Forms_Raw'!D21) -> Rectoria | E21: =IF('01_Forms_Raw'!E21="","",'01_Forms_Raw'!E21) -> Lidia Cala | F21: =IF('01_Forms_Raw'!F21="","",'01_Forms_Raw'!F21) -> Secretaria | G21: =IF('01_Forms_Raw'!G21="","",'01_Forms_Raw'!G21) -> rectoriaunimetro@unimetro.edu.co | H21: =IF('01_Forms_Raw'!I21="","",'01_Forms_Raw'!I21) -> Miniblocks - pieza uso interno unimetro | I21: =IF('01_Forms_Raw'!J21="","",'01_Forms_Raw'!J21) -> MiniBlocks | J21: =IF('01_Forms_Raw'!K21="","",VALUE('01_Forms_Raw'!K21)) -> 1000 | K21: =IF('01_Forms_Raw'!L21="","",'01_Forms_Raw'!L21) -> 46295 | L21: =IF('01_Forms_Raw'!M21="","",'01_Forms_Raw'!M21) -> Se requieren 1000 unidades de miniblocks.Se utizará material del inventario de la Imprenta UM que se replazará con material del pedido#016 | M21: Programado | N21: Aprobada para OT | O21: =IF(A21="","",IF(AND(D21<>"",E21<>"",H21<>"",I21<>"",J21<>"",K21<>""),"Completa","Incompleta")) -> Completa | P21: =IF(A21="","",K21-C21) -> 36 | Q21: =IF(A21="","",IF(P21<3,"Riesgo SLA",IF(P21<7,"Corto","OK"))) -> OK | R21: =IF(A21="","","OT-UM-"&TEXT(C21,"yyyymm")&"-"&TEXT(A21,"000")) -> OT-UM-202608-020 | S21: =IF(A21="","",IF(O21="Completa","Sí","No")) -> Sí | T21: =IF(A21="","",IF(O21="Completa","Lista para OT","Completar brief antes de pasar a diseño")) -> Lista para OT
A22: =IF('01_Forms_Raw'!A22="","",'01_Forms_Raw'!A22) -> 21 | B22: =IF('01_Forms_Raw'!B22="","",'01_Forms_Raw'!B22) -> 46260 | C22: =IF('01_Forms_Raw'!H22="","",'01_Forms_Raw'!H22) -> 46260 | D22: =IF('01_Forms_Raw'!D22="","",'01_Forms_Raw'!D22) -> Vicerrectoria - Direccion de bienestar universitario | E22: =IF('01_Forms_Raw'!E22="","",'01_Forms_Raw'!E22) -> Katty Aguas Gamarra | F22: =IF('01_Forms_Raw'!F22="","",'01_Forms_Raw'!F22) -> Coordinadora de Desarrollo Humano | G22: =IF('01_Forms_Raw'!G22="","",'01_Forms_Raw'!G22) -> desarrollohumano@unimetro.edu.co | H22: =IF('01_Forms_Raw'!I22="","",'01_Forms_Raw'!I22) -> Separadores de libros sobre salud mental | I22: =IF('01_Forms_Raw'!J22="","",'01_Forms_Raw'!J22) -> Separadores de libros | J22: =IF('01_Forms_Raw'!K22="","",VALUE('01_Forms_Raw'!K22)) -> 1000 | K22: =IF('01_Forms_Raw'!L22="","",'01_Forms_Raw'!L22) -> 46274 | L22: =IF('01_Forms_Raw'!M22="","",'01_Forms_Raw'!M22) -> Estos separadores se entregarán el dia 10 de septiembre en actividad masiva sobre prevención del suicidio. | M22: Programado | N22: Aprobada para OT | O22: =IF(A22="","",IF(AND(D22<>"",E22<>"",H22<>"",I22<>"",J22<>"",K22<>""),"Completa","Incompleta")) -> Completa | P22: =IF(A22="","",K22-C22) -> 14 | Q22: =IF(A22="","",IF(P22<3,"Riesgo SLA",IF(P22<7,"Corto","OK"))) -> OK | R22: =IF(A22="","","OT-UM-"&TEXT(C22,"yyyymm")&"-"&TEXT(A22,"000")) -> OT-UM-202608-021 | S22: =IF(A22="","",IF(O22="Completa","Sí","No")) -> Sí | T22: =IF(A22="","",IF(O22="Completa","Lista para OT","Completar brief antes de pasar a diseño")) -> Lista para OT
... A29: =IF('01_Forms_Raw'!A29="","",'01_Forms_Raw'!A29) -> 28 | B29: =IF('01_Forms_Raw'!B29="","",'01_Forms_Raw'!B29) -> 46297.648 | C29: =IF('01_Forms_Raw'!H29="","",'01_Forms_Raw'!H29) -> 46300 | D29: =IF('01_Forms_Raw'!D29="","",'01_Forms_Raw'!D29) -> Vicerrectoria - Direccion de bienestar universitario | E29: =IF('01_Forms_Raw'!E29="","",'01_Forms_Raw'!E29) -> Katty Aguas Gamarra | F29: =IF('01_Forms_Raw'!F29="","",'01_Forms_Raw'!F29) -> Coordinadora de Desarrollo Humano | G29: =IF('01_Forms_Raw'!G29="","",'01_Forms_Raw'!G29) -> desarrollohumano@unimetro.edu.co | H29: =IF('01_Forms_Raw'!I29="","",'01_Forms_Raw'!I29) -> Mini Agendas | I29: =IF('01_Forms_Raw'!J29="","",'01_Forms_Raw'!J29) -> Mini Agendas o Libretas | J29: =IF('01_Forms_Raw'!K29="","",VALUE('01_Forms_Raw'!K29)) -> 60 | K29: =IF('01_Forms_Raw'!L29="","",'01_Forms_Raw'!L29) -> 46314 | L29: =IF('01_Forms_Raw'!M29="","",'01_Forms_Raw'!M29) -> 60 mini agendas color rosa con un diseño simple. | M29: Urgente | N29: Validada | O29: =IF(A29="","",IF(AND(D29<>"",E29<>"",H29<>"",I29<>"",J29<>"",K29<>""),"Completa","Incompleta")) -> Completa | P29: =IF(A29="","",K29-C29) -> 14 | Q29: =IF(A29="","",IF(P29<3,"Riesgo SLA",IF(P29<7,"Corto","OK"))) -> OK | R29: =IF(A29="","","OT-UM-"&TEXT(C29,"yyyymm")&"-"&TEXT(A29,"000")) -> OT-UM-202610-028 | S29: =IF(A29="","",IF(O29="Completa","Sí","No")) -> Sí | T29: =IF(A29="","",IF(O29="Completa","Lista para OT","Completar brief antes de pasar a diseño")) -> Lista para OT
A30: =IF('01_Forms_Raw'!A30="","",'01_Forms_Raw'!A30) | B30: =IF('01_Forms_Raw'!B30="","",'01_Forms_Raw'!B30) | C30: =IF('01_Forms_Raw'!H30="","",'01_Forms_Raw'!H30) | D30: =IF('01_Forms_Raw'!D30="","",'01_Forms_Raw'!D30) | E30: =IF('01_Forms_Raw'!E30="","",'01_Forms_Raw'!E30) | F30: =IF('01_Forms_Raw'!F30="","",'01_Forms_Raw'!F30) | G30: =IF('01_Forms_Raw'!G30="","",'01_Forms_Raw'!G30) | H30: =IF('01_Forms_Raw'!I30="","",'01_Forms_Raw'!I30) | I30: =IF('01_Forms_Raw'!J30="","",'01_Forms_Raw'!J30) | J30: =IF('01_Forms_Raw'!K30="","",VALUE('01_Forms_Raw'!K30)) | K30: =IF('01_Forms_Raw'!L30="","",'01_Forms_Raw'!L30) | L30: =IF('01_Forms_Raw'!M30="","",'01_Forms_Raw'!M30) | O30: =IF(A30="","",IF(AND(D30<>"",E30<>"",H30<>"",I30<>"",J30<>"",K30<>""),"Completa","Incompleta")) | P30: =IF(A30="","",K30-C30) | Q30: =IF(A30="","",IF(P30<3,"Riesgo SLA",IF(P30<7,"Corto","OK"))) | R30: =IF(A30="","","OT-UM-"&TEXT(C30,"yyyymm")&"-"&TEXT(A30,"000")) | S30: =IF(A30="","",IF(O30="Completa","Sí","No")) | T30: =IF(A30="","",IF(O30="Completa","Lista para OT","Completar brief antes de pasar a diseño"))
A31: =IF('01_Forms_Raw'!A31="","",'01_Forms_Raw'!A31) | B31: =IF('01_Forms_Raw'!B31="","",'01_Forms_Raw'!B31) | C31: =IF('01_Forms_Raw'!H31="","",'01_Forms_Raw'!H31) | D31: =IF('01_Forms_Raw'!D31="","",'01_Forms_Raw'!D31) | E31: =IF('01_Forms_Raw'!E31="","",'01_Forms_Raw'!E31) | F31: =IF('01_Forms_Raw'!F31="","",'01_Forms_Raw'!F31) | G31: =IF('01_Forms_Raw'!G31="","",'01_Forms_Raw'!G31) | H31: =IF('01_Forms_Raw'!I31="","",'01_Forms_Raw'!I31) | I31: =IF('01_Forms_Raw'!J31="","",'01_Forms_Raw'!J31) | J31: =IF('01_Forms_Raw'!K31="","",VALUE('01_Forms_Raw'!K31)) | K31: =IF('01_Forms_Raw'!L31="","",'01_Forms_Raw'!L31) | L31: =IF('01_Forms_Raw'!M31="","",'01_Forms_Raw'!M31) | O31: =IF(A31="","",IF(AND(D31<>"",E31<>"",H31<>"",I31<>"",J31<>"",K31<>""),"Completa","Incompleta")) | P31: =IF(A31="","",K31-C31) | Q31: =IF(A31="","",IF(P31<3,"Riesgo SLA",IF(P31<7,"Corto","OK"))) | R31: =IF(A31="","","OT-UM-"&TEXT(C31,"yyyymm")&"-"&TEXT(A31,"000")) | S31: =IF(A31="","",IF(O31="Completa","Sí","No")) | T31: =IF(A31="","",IF(O31="Completa","Lista para OT","Completar brief antes de pasar a diseño"))
A32: =IF('01_Forms_Raw'!A32="","",'01_Forms_Raw'!A32) | B32: =IF('01_Forms_Raw'!B32="","",'01_Forms_Raw'!B32) | C32: =IF('01_Forms_Raw'!H32="","",'01_Forms_Raw'!H32) | D32: =IF('01_Forms_Raw'!D32="","",'01_Forms_Raw'!D32) | E32: =IF('01_Forms_Raw'!E32="","",'01_Forms_Raw'!E32) | F32: =IF('01_Forms_Raw'!F32="","",'01_Forms_Raw'!F32) | G32: =IF('01_Forms_Raw'!G32="","",'01_Forms_Raw'!G32) | H32: =IF('01_Forms_Raw'!I32="","",'01_Forms_Raw'!I32) | I32: =IF('01_Forms_Raw'!J32="","",'01_Forms_Raw'!J32) | J32: =IF('01_Forms_Raw'!K32="","",VALUE('01_Forms_Raw'!K32)) | K32: =IF('01_Forms_Raw'!L32="","",'01_Forms_Raw'!L32) | L32: =IF('01_Forms_Raw'!M32="","",'01_Forms_Raw'!M32) | O32: =IF(A32="","",IF(AND(D32<>"",E32<>"",H32<>"",I32<>"",J32<>"",K32<>""),"Completa","Incompleta")) | P32: =IF(A32="","",K32-C32) | Q32: =IF(A32="","",IF(P32<3,"Riesgo SLA",IF(P32<7,"Corto","OK"))) | R32: =IF(A32="","","OT-UM-"&TEXT(C32,"yyyymm")&"-"&TEXT(A32,"000")) | S32: =IF(A32="","",IF(O32="Completa","Sí","No")) | T32: =IF(A32="","",IF(O32="Completa","Lista para OT","Completar brief antes de pasar a diseño"))
A33: =IF('01_Forms_Raw'!A33="","",'01_Forms_Raw'!A33) | B33: =IF('01_Forms_Raw'!B33="","",'01_Forms_Raw'!B33) | C33: =IF('01_Forms_Raw'!H33="","",'01_Forms_Raw'!H33) | D33: =IF('01_Forms_Raw'!D33="","",'01_Forms_Raw'!D33) | E33: =IF('01_Forms_Raw'!E33="","",'01_Forms_Raw'!E33) | F33: =IF('01_Forms_Raw'!F33="","",'01_Forms_Raw'!F33) | G33: =IF('01_Forms_Raw'!G33="","",'01_Forms_Raw'!G33) | H33: =IF('01_Forms_Raw'!I33="","",'01_Forms_Raw'!I33) | I33: =IF('01_Forms_Raw'!J33="","",'01_Forms_Raw'!J33) | J33: =IF('01_Forms_Raw'!K33="","",VALUE('01_Forms_Raw'!K33)) | K33: =IF('01_Forms_Raw'!L33="","",'01_Forms_Raw'!L33) | L33: =IF('01_Forms_Raw'!M33="","",'01_Forms_Raw'!M33) | O33: =IF(A33="","",IF(AND(D33<>"",E33<>"",H33<>"",I33<>"",J33<>"",K33<>""),"Completa","Incompleta")) | P33: =IF(A33="","",K33-C33) | Q33: =IF(A33="","",IF(P33<3,"Riesgo SLA",IF(P33<7,"Corto","OK"))) | R33: =IF(A33="","","OT-UM-"&TEXT(C33,"yyyymm")&"-"&TEXT(A33,"000")) | S33: =IF(A33="","",IF(O33="Completa","Sí","No")) | T33: =IF(A33="","",IF(O33="Completa","Lista para OT","Completar brief antes de pasar a diseño"))
A34: =IF('01_Forms_Raw'!A34="","",'01_Forms_Raw'!A34) | B34: =IF('01_Forms_Raw'!B34="","",'01_Forms_Raw'!B34) | C34: =IF('01_Forms_Raw'!H34="","",'01_Forms_Raw'!H34) | D34: =IF('01_Forms_Raw'!D34="","",'01_Forms_Raw'!D34) | E34: =IF('01_Forms_Raw'!E34="","",'01_Forms_Raw'!E34) | F34: =IF('01_Forms_Raw'!F34="","",'01_Forms_Raw'!F34) | G34: =IF('01_Forms_Raw'!G34="","",'01_Forms_Raw'!G34) | H34: =IF('01_Forms_Raw'!I34="","",'01_Forms_Raw'!I34) | I34: =IF('01_Forms_Raw'!J34="","",'01_Forms_Raw'!J34) | J34: =IF('01_Forms_Raw'!K34="","",VALUE('01_Forms_Raw'!K34)) | K34: =IF('01_Forms_Raw'!L34="","",'01_Forms_Raw'!L34) | L34: =IF('01_Forms_Raw'!M34="","",'01_Forms_Raw'!M34) | O34: =IF(A34="","",IF(AND(D34<>"",E34<>"",H34<>"",I34<>"",J34<>"",K34<>""),"Completa","Incompleta")) | P34: =IF(A34="","",K34-C34) | Q34: =IF(A34="","",IF(P34<3,"Riesgo SLA",IF(P34<7,"Corto","OK"))) | R34: =IF(A34="","","OT-UM-"&TEXT(C34,"yyyymm")&"-"&TEXT(A34,"000")) | S34: =IF(A34="","",IF(O34="Completa","Sí","No")) | T34: =IF(A34="","",IF(O34="Completa","Lista para OT","Completar brief antes de pasar a diseño"))
A35: =IF('01_Forms_Raw'!A35="","",'01_Forms_Raw'!A35) | B35: =IF('01_Forms_Raw'!B35="","",'01_Forms_Raw'!B35) | C35: =IF('01_Forms_Raw'!H35="","",'01_Forms_Raw'!H35) | D35: =IF('01_Forms_Raw'!D35="","",'01_Forms_Raw'!D35) | E35: =IF('01_Forms_Raw'!E35="","",'01_Forms_Raw'!E35) | F35: =IF('01_Forms_Raw'!F35="","",'01_Forms_Raw'!F35) | G35: =IF('01_Forms_Raw'!G35="","",'01_Forms_Raw'!G35) | H35: =IF('01_Forms_Raw'!I35="","",'01_Forms_Raw'!I35) | I35: =IF('01_Forms_Raw'!J35="","",'01_Forms_Raw'!J35) | J35: =IF('01_Forms_Raw'!K35="","",VALUE('01_Forms_Raw'!K35)) | K35: =IF('01_Forms_Raw'!L35="","",'01_Forms_Raw'!L35) | L35: =IF('01_Forms_Raw'!M35="","",'01_Forms_Raw'!M35) | O35: =IF(A35="","",IF(AND(D35<>"",E35<>"",H35<>"",I35<>"",J35<>"",K35<>""),"Completa","Incompleta")) | P35: =IF(A35="","",K35-C35) | Q35: =IF(A35="","",IF(P35<3,"Riesgo SLA",IF(P35<7,"Corto","OK"))) | R35: =IF(A35="","","OT-UM-"&TEXT(C35,"yyyymm")&"-"&TEXT(A35,"000")) | S35: =IF(A35="","",IF(O35="Completa","Sí","No")) | T35: =IF(A35="","",IF(O35="Completa","Lista para OT","Completar brief antes de pasar a diseño"))
A36: =IF('01_Forms_Raw'!A36="","",'01_Forms_Raw'!A36) | B36: =IF('01_Forms_Raw'!B36="","",'01_Forms_Raw'!B36) | C36: =IF('01_Forms_Raw'!H36="","",'01_Forms_Raw'!H36) | D36: =IF('01_Forms_Raw'!D36="","",'01_Forms_Raw'!D36) | E36: =IF('01_Forms_Raw'!E36="","",'01_Forms_Raw'!E36) | F36: =IF('01_Forms_Raw'!F36="","",'01_Forms_Raw'!F36) | G36: =IF('01_Forms_Raw'!G36="","",'01_Forms_Raw'!G36) | H36: =IF('01_Forms_Raw'!I36="","",'01_Forms_Raw'!I36) | I36: =IF('01_Forms_Raw'!J36="","",'01_Forms_Raw'!J36) | J36: =IF('01_Forms_Raw'!K36="","",VALUE('01_Forms_Raw'!K36)) | K36: =IF('01_Forms_Raw'!L36="","",'01_Forms_Raw'!L36) | L36: =IF('01_Forms_Raw'!M36="","",'01_Forms_Raw'!M36) | O36: =IF(A36="","",IF(AND(D36<>"",E36<>"",H36<>"",I36<>"",J36<>"",K36<>""),"Completa","Incompleta")) | P36: =IF(A36="","",K36-C36) | Q36: =IF(A36="","",IF(P36<3,"Riesgo SLA",IF(P36<7,"Corto","OK"))) | R36: =IF(A36="","","OT-UM-"&TEXT(C36,"yyyymm")&"-"&TEXT(A36,"000")) | S36: =IF(A36="","",IF(O36="Completa","Sí","No")) | T36: =IF(A36="","",IF(O36="Completa","Lista para OT","Completar brief antes de pasar a diseño"))
A37: =IF('01_Forms_Raw'!A37="","",'01_Forms_Raw'!A37) | B37: =IF('01_Forms_Raw'!B37="","",'01_Forms_Raw'!B37) | C37: =IF('01_Forms_Raw'!H37="","",'01_Forms_Raw'!H37) | D37: =IF('01_Forms_Raw'!D37="","",'01_Forms_Raw'!D37) | E37: =IF('01_Forms_Raw'!E37="","",'01_Forms_Raw'!E37) | F37: =IF('01_Forms_Raw'!F37="","",'01_Forms_Raw'!F37) | G37: =IF('01_Forms_Raw'!G37="","",'01_Forms_Raw'!G37) | H37: =IF('01_Forms_Raw'!I37="","",'01_Forms_Raw'!I37) | I37: =IF('01_Forms_Raw'!J37="","",'01_Forms_Raw'!J37) | J37: =IF('01_Forms_Raw'!K37="","",VALUE('01_Forms_Raw'!K37)) | K37: =IF('01_Forms_Raw'!L37="","",'01_Forms_Raw'!L37) | L37: =IF('01_Forms_Raw'!M37="","",'01_Forms_Raw'!M37) | O37: =IF(A37="","",IF(AND(D37<>"",E37<>"",H37<>"",I37<>"",J37<>"",K37<>""),"Completa","Incompleta")) | P37: =IF(A37="","",K37-C37) | Q37: =IF(A37="","",IF(P37<3,"Riesgo SLA",IF(P37<7,"Corto","OK"))) | R37: =IF(A37="","","OT-UM-"&TEXT(C37,"yyyymm")&"-"&TEXT(A37,"000")) | S37: =IF(A37="","",IF(O37="Completa","Sí","No")) | T37: =IF(A37="","",IF(O37="Completa","Lista para OT","Completar brief antes de pasar a diseño"))
A38: =IF('01_Forms_Raw'!A38="","",'01_Forms_Raw'!A38) | B38: =IF('01_Forms_Raw'!B38="","",'01_Forms_Raw'!B38) | C38: =IF('01_Forms_Raw'!H38="","",'01_Forms_Raw'!H38) | D38: =IF('01_Forms_Raw'!D38="","",'01_Forms_Raw'!D38) | E38: =IF('01_Forms_Raw'!E38="","",'01_Forms_Raw'!E38) | F38: =IF('01_Forms_Raw'!F38="","",'01_Forms_Raw'!F38) | G38: =IF('01_Forms_Raw'!G38="","",'01_Forms_Raw'!G38) | H38: =IF('01_Forms_Raw'!I38="","",'01_Forms_Raw'!I38) | I38: =IF('01_Forms_Raw'!J38="","",'01_Forms_Raw'!J38) | J38: =IF('01_Forms_Raw'!K38="","",VALUE('01_Forms_Raw'!K38)) | K38: =IF('01_Forms_Raw'!L38="","",'01_Forms_Raw'!L38) | L38: =IF('01_Forms_Raw'!M38="","",'01_Forms_Raw'!M38) | O38: =IF(A38="","",IF(AND(D38<>"",E38<>"",H38<>"",I38<>"",J38<>"",K38<>""),"Completa","Incompleta")) | P38: =IF(A38="","",K38-C38) | Q38: =IF(A38="","",IF(P38<3,"Riesgo SLA",IF(P38<7,"Corto","OK"))) | R38: =IF(A38="","","OT-UM-"&TEXT(C38,"yyyymm")&"-"&TEXT(A38,"000")) | S38: =IF(A38="","",IF(O38="Completa","Sí","No")) | T38: =IF(A38="","",IF(O38="Completa","Lista para OT","Completar brief antes de pasar a diseño"))
A39: =IF('01_Forms_Raw'!A39="","",'01_Forms_Raw'!A39) | B39: =IF('01_Forms_Raw'!B39="","",'01_Forms_Raw'!B39) | C39: =IF('01_Forms_Raw'!H39="","",'01_Forms_Raw'!H39) | D39: =IF('01_Forms_Raw'!D39="","",'01_Forms_Raw'!D39) | E39: =IF('01_Forms_Raw'!E39="","",'01_Forms_Raw'!E39) | F39: =IF('01_Forms_Raw'!F39="","",'01_Forms_Raw'!F39) | G39: =IF('01_Forms_Raw'!G39="","",'01_Forms_Raw'!G39) | H39: =IF('01_Forms_Raw'!I39="","",'01_Forms_Raw'!I39) | I39: =IF('01_Forms_Raw'!J39="","",'01_Forms_Raw'!J39) | J39: =IF('01_Forms_Raw'!K39="","",VALUE('01_Forms_Raw'!K39)) | K39: =IF('01_Forms_Raw'!L39="","",'01_Forms_Raw'!L39) | L39: =IF('01_Forms_Raw'!M39="","",'01_Forms_Raw'!M39) | O39: =IF(A39="","",IF(AND(D39<>"",E39<>"",H39<>"",I39<>"",J39<>"",K39<>""),"Completa","Incompleta")) | P39: =IF(A39="","",K39-C39) | Q39: =IF(A39="","",IF(P39<3,"Riesgo SLA",IF(P39<7,"Corto","OK"))) | R39: =IF(A39="","","OT-UM-"&TEXT(C39,"yyyymm")&"-"&TEXT(A39,"000")) | S39: =IF(A39="","",IF(O39="Completa","Sí","No")) | T39: =IF(A39="","",IF(O39="Completa","Lista para OT","Completar brief antes de pasar a diseño"))
A40: =IF('01_Forms_Raw'!A40="","",'01_Forms_Raw'!A40) | B40: =IF('01_Forms_Raw'!B40="","",'01_Forms_Raw'!B40) | C40: =IF('01_Forms_Raw'!H40="","",'01_Forms_Raw'!H40) | D40: =IF('01_Forms_Raw'!D40="","",'01_Forms_Raw'!D40) | E40: =IF('01_Forms_Raw'!E40="","",'01_Forms_Raw'!E40) | F40: =IF('01_Forms_Raw'!F40="","",'01_Forms_Raw'!F40) | G40: =IF('01_Forms_Raw'!G40="","",'01_Forms_Raw'!G40) | H40: =IF('01_Forms_Raw'!I40="","",'01_Forms_Raw'!I40) | I40: =IF('01_Forms_Raw'!J40="","",'01_Forms_Raw'!J40) | J40: =IF('01_Forms_Raw'!K40="","",VALUE('01_Forms_Raw'!K40)) | K40: =IF('01_Forms_Raw'!L40="","",'01_Forms_Raw'!L40) | L40: =IF('01_Forms_Raw'!M40="","",'01_Forms_Raw'!M40) | O40: =IF(A40="","",IF(AND(D40<>"",E40<>"",H40<>"",I40<>"",J40<>"",K40<>""),"Completa","Incompleta")) | P40: =IF(A40="","",K40-C40) | Q40: =IF(A40="","",IF(P40<3,"Riesgo SLA",IF(P40<7,"Corto","OK"))) | R40: =IF(A40="","","OT-UM-"&TEXT(C40,"yyyymm")&"-"&TEXT(A40,"000")) | S40: =IF(A40="","",IF(O40="Completa","Sí","No")) | T40: =IF(A40="","",IF(O40="Completa","Lista para OT","Completar brief antes de pasar a diseño"))
A41: =IF('01_Forms_Raw'!A41="","",'01_Forms_Raw'!A41) | B41: =IF('01_Forms_Raw'!B41="","",'01_Forms_Raw'!B41) | C41: =IF('01_Forms_Raw'!H41="","",'01_Forms_Raw'!H41) | D41: =IF('01_Forms_Raw'!D41="","",'01_Forms_Raw'!D41) | E41: =IF('01_Forms_Raw'!E41="","",'01_Forms_Raw'!E41) | F41: =IF('01_Forms_Raw'!F41="","",'01_Forms_Raw'!F41) | G41: =IF('01_Forms_Raw'!G41="","",'01_Forms_Raw'!G41) | H41: =IF('01_Forms_Raw'!I41="","",'01_Forms_Raw'!I41) | I41: =IF('01_Forms_Raw'!J41="","",'01_Forms_Raw'!J41) | J41: =IF('01_Forms_Raw'!K41="","",VALUE('01_Forms_Raw'!K41)) | K41: =IF('01_Forms_Raw'!L41="","",'01_Forms_Raw'!L41) | L41: =IF('01_Forms_Raw'!M41="","",'01_Forms_Raw'!M41) | O41: =IF(A41="","",IF(AND(D41<>"",E41<>"",H41<>"",I41<>"",J41<>"",K41<>""),"Completa","Incompleta")) | P41: =IF(A41="","",K41-C41) | Q41: =IF(A41="","",IF(P41<3,"Riesgo SLA",IF(P41<7,"Corto","OK"))) | R41: =IF(A41="","","OT-UM-"&TEXT(C41,"yyyymm")&"-"&TEXT(A41,"000")) | S41: =IF(A41="","",IF(O41="Completa","Sí","No")) | T41: =IF(A41="","",IF(O41="Completa","Lista para OT","Completar brief antes de pasar a diseño"))
... A201: =IF('01_Forms_Raw'!A201="","",'01_Forms_Raw'!A201) | B201: =IF('01_Forms_Raw'!B201="","",'01_Forms_Raw'!B201) | C201: =IF('01_Forms_Raw'!H201="","",'01_Forms_Raw'!H201) | D201: =IF('01_Forms_Raw'!D201="","",'01_Forms_Raw'!D201) | E201: =IF('01_Forms_Raw'!E201="","",'01_Forms_Raw'!E201) | F201: =IF('01_Forms_Raw'!F201="","",'01_Forms_Raw'!F201) | G201: =IF('01_Forms_Raw'!G201="","",'01_Forms_Raw'!G201) | H201: =IF('01_Forms_Raw'!I201="","",'01_Forms_Raw'!I201) | I201: =IF('01_Forms_Raw'!J201="","",'01_Forms_Raw'!J201) | J201: =IF('01_Forms_Raw'!K201="","",VALUE('01_Forms_Raw'!K201)) | K201: =IF('01_Forms_Raw'!L201="","",'01_Forms_Raw'!L201) | L201: =IF('01_Forms_Raw'!M201="","",'01_Forms_Raw'!M201) | O201: =IF(A201="","",IF(AND(D201<>"",E201<>"",H201<>"",I201<>"",J201<>"",K201<>""),"Completa","Incompleta")) | P201: =IF(A201="","",K201-C201) | Q201: =IF(A201="","",IF(P201<3,"Riesgo SLA",IF(P201<7,"Corto","OK"))) | R201: =IF(A201="","","OT-UM-"&TEXT(C201,"yyyymm")&"-"&TEXT(A201,"000")) | S201: =IF(A201="","",IF(O201="Completa","Sí","No")) | T201: =IF(A201="","",IF(O201="Completa","Lista para OT","Completar brief antes de pasar a diseño"))

Sheet 03_OT_Maestra
A1: OT Maestra V1 - Integrada Formulario + Diseño + Preprensa + Producción
A2: Campos verdes = extraídos del formulario / Campos amarillos = input Diseño, Preprensa, Producción y Cierre
